<mujoco model="robotic_arm_v7_simple_grasp_scene">
  <compiler angle="radian" autolimits="true" />
  <option timestep="0.002" gravity="0 0 -9.81" integrator="implicitfast" iterations="100" ls_iterations="50" cone="elliptic" />
  <default>
    <joint damping="0.08" armature="0.001" />
    <geom condim="3" friction="1 0.005 0.0001" />
  </default>
  <compiler angle="radian" />
  <asset>
    <mesh name="base_link" content_type="model/stl" file="../assets/meshes/base_link.STL" />
    <mesh name="link1" content_type="model/stl" file="../assets/meshes/link1.STL" />
    <mesh name="link2" content_type="model/stl" file="../assets/meshes/link2.STL" />
    <mesh name="link3" content_type="model/stl" file="../assets/meshes/link3.STL" />
    <mesh name="link4" content_type="model/stl" file="../assets/meshes/link4.STL" />
    <mesh name="link5" content_type="model/stl" file="../assets/meshes/link5.STL" />
    <mesh name="link6" content_type="model/stl" file="../assets/meshes/link6.STL" />
    <mesh name="fin1" content_type="model/stl" file="../assets/meshes/fin1.STL" />
    <mesh name="fin2" content_type="model/stl" file="../assets/meshes/fin2.STL" />
  </asset>
  <worldbody>
    <light name="main_light" pos="0 -1.5 2" dir="0 1 -1.5" />
    <camera name="overview" pos="1.6 -1.8 1.3" euler="1.1 0 0.72" />
    <geom name="ground" type="plane" pos="0 0 -0.02" size="3 3 0.02" rgba="0.75 0.75 0.75 1" friction="3 0.5 0.05" condim="6" solref="0.001 1" solimp="0.99 0.999 0.0001" contype="1" conaffinity="1" />
    <geom type="mesh" rgba="0.792157 0.819608 0.933333 1" mesh="base_link" name="base_link_visual" contype="2" conaffinity="0" group="1" density="0" condim="6" solref="0.001 1" solimp="0.99 0.999 0.0001" friction="5 1 0.1" />
    <body name="link1" pos="0 0 0.6" quat="-3.67321e-06 0 0 1">
      <inertial pos="0.197136 -1.59976e-07 0.0526643" quat="0.5 0.5 0.5 0.5" mass="4.44205" diaginertia="0.1116 0.111433 0.00575246" />
      <joint name="joint1" pos="0 0 0" axis="0 0 -1" range="-3.14 3.14" actuatorfrcrange="-100 100" />
      <geom type="mesh" rgba="1 1 1 1" mesh="link1" name="link1_visual" contype="2" conaffinity="0" group="1" density="0" condim="6" solref="0.001 1" solimp="0.99 0.999 0.0001" friction="5 1 0.1" />
      <body name="link2" pos="0.4 0 0">
        <inertial pos="-0.000738403 0.197136 -0.0634026" quat="0.512794 0.512635 -0.483844 0.490044" mass="4.44205" diaginertia="0.111539 0.111507 0.00574923" />
        <joint name="joint2" pos="0 0 0" axis="0 0 -1" range="-3.14 3.14" actuatorfrcrange="-100 100" />
        <geom type="mesh" rgba="1 1 1 1" mesh="link2" name="link2_visual" contype="2" conaffinity="0" group="1" density="0" condim="6" solref="0.001 1" solimp="0.99 0.999 0.0001" friction="5 1 0.1" />
        <body name="link3" pos="-0.055 0.4 -0.065" quat="0.499998 0.5 0.500002 0.5">
          <inertial pos="0.0398975 0 -0.0626423" quat="0.497692 0.502297 0.502297 0.497692" mass="2.32723" diaginertia="0.0113093 0.0112712 0.00383359" />
          <joint name="joint3" pos="0 0 0" axis="0 0 -1" range="-3.14 3.14" actuatorfrcrange="-100 100" damping="2.5" armature="0.05" />
          <geom type="mesh" rgba="1 1 1 1" mesh="link3" name="link3_visual" contype="2" conaffinity="0" group="1" density="0" condim="6" solref="0.001 1" solimp="0.99 0.999 0.0001" friction="5 1 0.1" />
          <body name="link4" pos="0.16 0 -0.065" quat="0.499998 0.5 0.500002 0.5">
            <inertial pos="0 -1.73683e-12 0.047952" mass="0.455426" diaginertia="0.00111346 0.000921461 0.000888619" />
            <joint name="joint4" pos="0 0 0" axis="0 0 1" range="-3.14 3.14" actuatorfrcrange="-100 100" damping="2.5" armature="0.05" />
            <geom type="mesh" rgba="1 1 1 1" mesh="link4" name="link4_visual" contype="2" conaffinity="0" group="1" density="0" condim="6" solref="0.001 1" solimp="0.99 0.999 0.0001" friction="5 1 0.1" />
            <body name="link5" pos="0.05 -0.05 0.1" quat="0.499998 0.5 0.500002 0.5">
              <inertial pos="0.05 -0.04 0.0484868" mass="1.93924" diaginertia="0.015873 0.015873 0.00205979" />
              <joint name="joint5" pos="0 0 0" axis="0 0 -1" type="slide" range="0 0.2" actuatorfrcrange="-100 100" />
              <geom type="mesh" rgba="0.796078 0.823529 0.937255 1" mesh="link5" name="link5_visual" contype="2" conaffinity="0" group="1" density="0" condim="6" solref="0.001 1" solimp="0.99 0.999 0.0001" friction="5 1 0.1" />
              <body name="link6" pos="0.05 -0.04 -0.11" quat="-2.59734e-06 -0.707105 0.707108 2.59735e-06">
                <inertial pos="0 1.73705e-12 0.0690013" quat="0.707107 0 0 0.707107" mass="0.897727" diaginertia="0.00214144 0.00160944 0.00151936" />
                <joint name="joint6" pos="0 0 0" axis="0 0 1" actuatorfrcrange="-100 100" damping="4.0" armature="0.08" />
                <geom type="mesh" rgba="1 1 1 1" mesh="link6" name="link6_visual" contype="2" conaffinity="0" group="1" density="0" condim="6" solref="0.001 1" solimp="0.99 0.999 0.0001" friction="5 1 0.1" />
                <body name="fin1" pos="-0.1 0.04 0.12" quat="0.499998 -0.5 0.500002 -0.5">
                  <inertial pos="0.04 -0.0468605 0.0575" quat="0 0.707107 0 0.707107" mass="0.301" diaginertia="0.0004287 0.00027036 0.000219794" />
                  <joint name="joint71" pos="0 0 0" axis="0 0 1" type="slide" range="-0.05 0.015" actuatorfrcrange="-100 100" damping="25.0" armature="0.02" />
                  <geom type="mesh" rgba="1 1 1 1" mesh="fin1" name="fin1_visual" contype="2" conaffinity="0" group="1" density="0" condim="6" solref="0.001 1" solimp="0.99 0.999 0.0001" friction="200 20 2" />
                  <site name="left_finger_tip_site" pos="0.04 -0.046 0.0575" size="0.006" rgba="0.8 0 0 1" />
                </body>
                <body name="fin2" pos="-0.1 0.04 0.12" quat="0.499998 -0.5 0.500002 -0.5">
                  <inertial pos="0.04 -0.0468605 0.1425" quat="0 0.707107 0 0.707107" mass="0.301" diaginertia="0.0004287 0.00027036 0.000219794" />
                  <joint name="joint72" pos="0 0 0" axis="0 0 1" type="slide" range="-0.015 0.05" actuatorfrcrange="-100 100" damping="25.0" armature="0.02" />
                  <geom type="mesh" rgba="1 1 1 1" mesh="fin2" name="fin2_visual" contype="2" conaffinity="0" group="1" density="0" condim="6" solref="0.001 1" solimp="0.99 0.999 0.0001" friction="200 20 2" />
                  <site name="right_finger_tip_site" pos="0.04 -0.046 0.1425" size="0.006" rgba="0 0 0.8 1" />
                </body>
                <site name="ee_site" pos="0 0 0.22" size="0.008" rgba="0 0.8 0 1" />
                <site name="peg_tip_site" pos="0.04 -0.046 0.10" size="0.006" rgba="1 0.5 0 1" />
              </body>
            </body>
          </body>
        </body>
      </body>
    </body>
    <body name="grasp_object" pos="0 0 0">
      <freejoint name="grasp_object_freejoint" />
      <geom name="grasp_object_collision" type="cylinder" size="0.058 0.11" mass="0.01" rgba="0.9 0.45 0.15 1" friction="200 20 2" condim="6" solref="0.001 1" solimp="0.99 0.999 0.0001" contype="1" conaffinity="3" />
    </body>
  </worldbody>
  <actuator>
    <motor name="joint1_motor" joint="joint1" ctrllimited="true" ctrlrange="-90 90" />
    <motor name="joint2_motor" joint="joint2" ctrllimited="true" ctrlrange="-90 90" />
    <motor name="joint3_motor" joint="joint3" ctrllimited="true" ctrlrange="-220 220" />
    <motor name="joint4_motor" joint="joint4" ctrllimited="true" ctrlrange="-220 220" />
    <motor name="joint5_motor" joint="joint5" ctrllimited="true" ctrlrange="-180 180" />
    <motor name="joint6_motor" joint="joint6" ctrllimited="true" ctrlrange="-160 160" />
    <motor name="gripper_left_motor" joint="joint71" ctrllimited="true" ctrlrange="-95 95" />
    <motor name="gripper_right_motor" joint="joint72" ctrllimited="true" ctrlrange="-95 95" />
  </actuator>
</mujoco>
